Workbook

Sheet README
A1: Instruction | B1: Detail
A2: 1. Defensible Deletion Proof | B2: Every target in this list has zero METADATA activity (writes/modifications) for at least 365 days.
A3: 2. How to Validate Storage | B3: Run the SQL in the [Validation SQL (Storage)] column to verify the size and absolute last modified date.
A4: 3. How to Validate Usage | B4: Run the SQL in the [Validation SQL (Read/Usage)] column. If it returns 0 rows, NO ONE has queried this dataset in 180 days.
A5: 4. Safe Deletion Process | B5: Instead of DROP, consider setting a 7-day expiration (the "Scream Test"). If no one complains, the data auto-deletes.
A6: 5. Access Issues | B6: Refer to the [AccessIssues] sheet for a list of projects where the audit service account lacks permissions.
A9: Category | B9: Definition | C9: Detail
A10: Tranche 1 | B10: Stale Test/Temp | C10: Datasets with "test/temp/tmp" in the name AND no access in 180 days. Immediate deletion candidates.
A11: Tranche 2 | B11: High Saving Stale | C11: Production datasets > 100GB with no access in 180 days. Primary target for cost reduction.
A12: Tranche 3 | B12: Stale Production | C12: Small production datasets with no access in 180 days.
A13: Tranche 4 | B13: Active Test/Temp | C13: Datasets with "test/temp/tmp" in name but HAVE access history. Review for housekeeping.
A14: Column: Description | B14: Dataset Metadata | C14: Pulled from BigQuery SCHEMATA_OPTIONS. Helps identify ownership/purpose.
A15: Column: Last 5 Access | B15: Audit Trail | C15: Shows the most recent 5 jobs (Read or Write) including the user email and time.
A16: Column: Monthly Cost | B16: Financial Impact | C16: Estimated based on $0.02 per GB per month (standard logical storage).
A17: thg-influencer | B17: Inividual Project | C17: Charlie Stringer to review
A18: thg-ingenuity | B18: Inividual Project | C18: Charlie Stringer to review
A19: thg-central-marketing | B19: Inividual Project | C19: Charlie Stringer to review
A20: thg-seoclarity | B20: Inividual Project | C20: Charlie Stringer to review

Sheet Dashboard
A1: BigQuery Data Estate Cleanup — Dashboard
A2: Source: BQ-added-Data sheet
A4: KEY METRICS | D4: BY TRANCHE | S4: Full Name | T4: Short Name
A5: Total Datasets | B5: =COUNTA('BQ-added-Data'!A2:A2098) -> 2097 | D5: Tranche | E5: # Datasets | F5: Size (GB) | G5: Monthly Cost ($) | H5: Annual ($) | S5: =D6 -> Tranche 1: Abandoned Test/Temp (>1yr) | T5: T1
A6: Total Size (GB) | B6: =SUM('BQ-added-Data'!E2:E2098) -> 2164100.2 | D6: Tranche 1: Abandoned Test/Temp (>1yr) | E6: =COUNTIF('BQ-added-Data'!G:G,D6) -> 30 | F6: =SUMIF('BQ-added-Data'!G:G,D6,'BQ-added-Data'!E:E) -> 27106.86 | G6: =SUMIF('BQ-added-Data'!G:G,D6,'BQ-added-Data'!F:F) -> 542.15 | H6: =G6*12 -> 6505.8 | S6: =D7 -> Tranche 1.1: Abandoned Test/Temp (>1yr) | T6: T1.1
A7: Total Size (TB) | B7: =B6/1024 -> 2113.3791 | D7: Tranche 1.1: Abandoned Test/Temp (>1yr) | E7: =COUNTIF('BQ-added-Data'!G:G,"Tranche 1.1: Abandoned Test/Temp (>1yr)") -> 7 | F7: =SUMIF('BQ-added-Data'!G:G,"Tranche 1.1: Abandoned Test/Temp (>1yr)",'BQ-added-Data'!E:E) -> 387.33 | G7: =SUMIF('BQ-added-Data'!G:G,"Tranche 1.1: Abandoned Test/Temp (>1yr)",'BQ-added-Data'!F:F) -> 7.75 | H7: =G7*12 -> 93 | S7: =D9 -> Tranche 2: Abandoned Large Prod (>1yr) | T7: T2
A8: Monthly Cost ($) | B8: =SUM('BQ-added-Data'!F2:F2098) -> 43281.69 | D8: Tranche 1 Subtotal | E8: =SUM(E6:E7) -> 37 | F8: =SUM(F6:F7) -> 27494.19 | G8: =SUM(G6:G7) -> 549.9 | H8: =G8*12 -> 6598.8 | S8: =D10 -> Tranche 2.1: Abandoned Large Prod (>1yr) | T8: T2.1
A9: Annualised Cost ($) | B9: =B8*12 -> 519380.28 | D9: Tranche 2: Abandoned Large Prod (>1yr) | E9: =COUNTIF('BQ-added-Data'!G:G,D9) -> 151 | F9: =SUMIF('BQ-added-Data'!G:G,D9,'BQ-added-Data'!E:E) -> 436588.6 | G9: =SUMIF('BQ-added-Data'!G:G,D9,'BQ-added-Data'!F:F) -> 8731.75 | H9: =G9*12 -> 104781 | S9: =D12 -> Tranche 3: Abandoned Small Prod (>1yr) | T9: T3
A10: Critical Priority Datasets | B10: =COUNTIF('BQ-added-Data'!H2:H2098,"Critical") -> 218 | D10: Tranche 2.1: Abandoned Large Prod (>1yr) | E10: =COUNTIF('BQ-added-Data'!G:G,"Tranche 2.1: Abandoned Large Prod (>1yr)") -> 23 | F10: =SUMIF('BQ-added-Data'!G:G,"Tranche 2.1: Abandoned Large Prod (>1yr)",'BQ-added-Data'!E:E) -> 9093.22 | G10: =SUMIF('BQ-added-Data'!G:G,"Tranche 2.1: Abandoned Large Prod (>1yr)",'BQ-added-Data'!F:F) -> 181.84 | H10: =G10*12 -> 2182.08 | S10: =D13 -> Tranche 3.1: Abandoned Small Prod (>1yr) | T10: T3.1
A11: Defensible Deletion Confirmed | B11: =COUNTIF('BQ-added-Data'!P2:P2098,"CONFIRMED: NO MODS > 1YR") -> 310 | D11: Tranche 2 Subtotal | E11: =SUM(E9:E10) -> 174 | F11: =SUM(F9:F10) -> 445681.82 | G11: =SUM(G9:G10) -> 8913.59 | H11: =G11*12 -> 106963.08 | S11: =D15 -> Tranche 4: Stale (No Access 180d, No Write >6mo) | T11: T4
A12: Distinct Projects | B12: {=SUMPRODUCT((('BQ-added-Data'!A2:A2098)<>"")/COUNTIF('BQ-added-Data'!A2:A2098,'BQ-added-Data'!A2:A2098&""))} -> 29 | D12: Tranche 3: Abandoned Small Prod (>1yr) | E12: =COUNTIF('BQ-added-Data'!G:G,D12) -> 643 | F12: =SUMIF('BQ-added-Data'!G:G,D12,'BQ-added-Data'!E:E) -> 7629.44 | G12: =SUMIF('BQ-added-Data'!G:G,D12,'BQ-added-Data'!F:F) -> 152.54 | H12: =G12*12 -> 1830.48 | S12: =D16 -> Tranche 4.1: Stale (No Access 180d, No Write >6mo) | T12: T4.1
D13: Tranche 3.1: Abandoned Small Prod (>1yr) | E13: =COUNTIF('BQ-added-Data'!G:G,"Tranche 3.1: Abandoned Small Prod (>1yr)") -> 367 | F13: =SUMIF('BQ-added-Data'!G:G,"Tranche 3.1: Abandoned Small Prod (>1yr)",'BQ-added-Data'!E:E) -> 3743.34 | G13: =SUMIF('BQ-added-Data'!G:G,"Tranche 3.1: Abandoned Small Prod (>1yr)",'BQ-added-Data'!F:F) -> 74.79 | H13: =G13*12 -> 897.48 | S13: =D18 -> Tranche 5: Active Test (Housekeeping) | T13: T5
D14: Tranche 3 Subtotal | E14: =SUM(E12:E13) -> 1010 | F14: =SUM(F12:F13) -> 11372.78 | G14: =SUM(G12:G13) -> 227.33 | H14: =G14*12 -> 2727.96 | S14: =D19 -> Tranche 5.1: Active Test (Housekeeping) | T14: T5.1
D15: Tranche 4: Stale (No Access 180d, No Write >6mo) | E15: =COUNTIF('BQ-added-Data'!G:G,D15) -> 20 | F15: =SUMIF('BQ-added-Data'!G:G,D15,'BQ-added-Data'!E:E) -> 4833.92 | G15: =SUMIF('BQ-added-Data'!G:G,D15,'BQ-added-Data'!F:F) -> 96.69 | H15: =G15*12 -> 1160.28 | S15: =D21 -> Active | T15: Active
D16: Tranche 4.1: Stale (No Access 180d, No Write >6mo) | E16: =COUNTIF('BQ-added-Data'!G:G,"Tranche 4.1: Stale (No Access 180d, No Write >6mo)") -> 19 | F16: =SUMIF('BQ-added-Data'!G:G,"Tranche 4.1: Stale (No Access 180d, No Write >6mo)",'BQ-added-Data'!E:E) -> 349.04 | G16: =SUMIF('BQ-added-Data'!G:G,"Tranche 4.1: Stale (No Access 180d, No Write >6mo)",'BQ-added-Data'!F:F) -> 6.99 | H16: =G16*12 -> 83.88 | S16: Low | T16: =G19 -> 35.82
D17: Tranche 4 Subtotal | E17: =SUM(E15:E16) -> 39 | F17: =SUM(F15:F16) -> 5182.96 | G17: =SUM(G15:G16) -> 103.68 | H17: =G17*12 -> 1244.16
D18: Tranche 5: Active Test (Housekeeping) | E18: =COUNTIF('BQ-added-Data'!G:G,D18) -> 44 | F18: =SUMIF('BQ-added-Data'!G:G,D18,'BQ-added-Data'!E:E) -> 27262.73 | G18: =SUMIF('BQ-added-Data'!G:G,D18,'BQ-added-Data'!F:F) -> 545.25 | H18: =G18*12 -> 6543 | S18: Project | T18: Monthly $
D19: Tranche 5.1: Active Test (Housekeeping) | E19: =COUNTIF('BQ-added-Data'!G:G,"Tranche 5.1: Active Test (Housekeeping)") -> 5 | F19: =SUMIF('BQ-added-Data'!G:G,"Tranche 5.1: Active Test (Housekeeping)",'BQ-added-Data'!E:E) -> 1791.03 | G19: =SUMIF('BQ-added-Data'!G:G,"Tranche 5.1: Active Test (Housekeeping)",'BQ-added-Data'!F:F) -> 35.82 | H19: =G19*12 -> 429.84 | S19: =D24 -> agile-bonbon-662 | T19: =G24 -> 14855.31
D20: Tranche 5 Subtotal | E20: =SUM(E18:E19) -> 49 | F20: =SUM(F18:F19) -> 29053.76 | G20: =SUM(G18:G19) -> 581.07 | H20: =G20*12 -> 6972.84 | S20: =D25 -> thg-ingenuity | T20: =G25 -> 890.72
D21: Active | E21: =COUNTIF('BQ-added-Data'!G:G,D21) -> 788 | F21: =SUMIF('BQ-added-Data'!G:G,D21,'BQ-added-Data'!E:E) -> 1645314.7 | G21: =SUMIF('BQ-added-Data'!G:G,D21,'BQ-added-Data'!F:F) -> 32906.12 | H21: =G21*12 -> 394873.44 | S21: =D26 -> the-hut-group | T21: =G26 -> 15712.67
D22: TOTAL | E22: =E8+E11+E14+E17+E20+E21 -> 2097 | F22: =F8+F11+F14+F17+F20+F21 -> 2164100.2 | G22: =G8+G11+G14+G17+G20+G21 -> 43281.69 | H22: =G22*12 -> 519380.28 | S22: =D27 -> vibrant-map-107910 | T22: =G27 -> 2953.03
D23: Project | E23: # Datasets | F23: Size (GB) | G23: Monthly Cost ($) | H23: Annual ($) | S23: =D28 -> thg-beauty | T23: =G28 -> 953.12
D24: agile-bonbon-662 | E24: =COUNTIF('BQ-added-Data'!A:A,D24) -> 915 | F24: =SUMIF('BQ-added-Data'!A:A,D24,'BQ-added-Data'!E:E) -> 742768.12 | G24: =SUMIF('BQ-added-Data'!A:A,D24,'BQ-added-Data'!F:F) -> 14855.31 | H24: =G24*12 -> 178263.72 | S24: =D29 -> thg-ml-dev | T24: =G29 -> 252.36
D25: thg-ingenuity | E25: =COUNTIF('BQ-added-Data'!A:A,D25) -> 534 | F25: =SUMIF('BQ-added-Data'!A:A,D25,'BQ-added-Data'!E:E) -> 44539.12 | G25: =SUMIF('BQ-added-Data'!A:A,D25,'BQ-added-Data'!F:F) -> 890.72 | H25: =G25*12 -> 10688.64 | S25: =D30 -> thg-central-marketing | T25: =G30 -> 3501.61
D26: the-hut-group | E26: =COUNTIF('BQ-added-Data'!A:A,D26) -> 114 | F26: =SUMIF('BQ-added-Data'!A:A,D26,'BQ-added-Data'!E:E) -> 785636.05 | G26: =SUMIF('BQ-added-Data'!A:A,D26,'BQ-added-Data'!F:F) -> 15712.67 | H26: =G26*12 -> 188552.04 | S26: =D31 -> thg-influencer | T26: =G31 -> 32.52
D27: vibrant-map-107910 | E27: =COUNTIF('BQ-added-Data'!A:A,D27) -> 79 | F27: =SUMIF('BQ-added-Data'!A:A,D27,'BQ-added-Data'!E:E) -> 147651.32 | G27: =SUMIF('BQ-added-Data'!A:A,D27,'BQ-added-Data'!F:F) -> 2953.03 | H27: =G27*12 -> 35436.36 | S27: =D32 -> thg-content | T27: =G32 -> 70.52
D28: thg-beauty | E28: =COUNTIF('BQ-added-Data'!A:A,D28) -> 145 | F28: =SUMIF('BQ-added-Data'!A:A,D28,'BQ-added-Data'!E:E) -> 47656.57 | G28: =SUMIF('BQ-added-Data'!A:A,D28,'BQ-added-Data'!F:F) -> 953.12 | H28: =G28*12 -> 11437.44 | S28: =D33 -> thg-seoclarity | T28: =G33 -> 45.7
D29: thg-ml-dev | E29: =COUNTIF('BQ-added-Data'!A:A,D29) -> 60 | F29: =SUMIF('BQ-added-Data'!A:A,D29,'BQ-added-Data'!E:E) -> 12618.19 | G29: =SUMIF('BQ-added-Data'!A:A,D29,'BQ-added-Data'!F:F) -> 252.36 | H29: =G29*12 -> 3028.32 | S29: All Others | T29: =G34 -> -39115.02
D30: thg-central-marketing | E30: =COUNTIF('BQ-added-Data'!A:A,D30) -> 66 | F30: =SUMIF('BQ-added-Data'!A:A,D30,'BQ-added-Data'!E:E) -> 175082.62 | G30: =SUMIF('BQ-added-Data'!A:A,D30,'BQ-added-Data'!F:F) -> 3501.61 | H30: =G30*12 -> 42019.32
D31: thg-influencer | E31: =COUNTIF('BQ-added-Data'!A:A,D31) -> 54 | F31: =SUMIF('BQ-added-Data'!A:A,D31,'BQ-added-Data'!E:E) -> 1628.41 | G31: =SUMIF('BQ-added-Data'!A:A,D31,'BQ-added-Data'!F:F) -> 32.52 | H31: =G31*12 -> 390.24
D32: thg-content | E32: =COUNTIF('BQ-added-Data'!A:A,D32) -> 5 | F32: =SUMIF('BQ-added-Data'!A:A,D32,'BQ-added-Data'!E:E) -> 3526.35 | G32: =SUMIF('BQ-added-Data'!A:A,D32,'BQ-added-Data'!F:F) -> 70.52 | H32: =G32*12 -> 846.24
D33: thg-seoclarity | E33: =COUNTIF('BQ-added-Data'!A:A,D33) -> 2 | F33: =SUMIF('BQ-added-Data'!A:A,D33,'BQ-added-Data'!E:E) -> 2285.07 | G33: =SUMIF('BQ-added-Data'!A:A,D33,'BQ-added-Data'!F:F) -> 45.7 | H33: =G33*12 -> 548.4
D34: All Others | E34: =E12-SUM(E24:E33) -> -1331 | F34: =F12-SUM(F24:F33) -> -1955762.4 | G34: =G12-SUM(G24:G33) -> -39115.02 | H34: =G34*12 -> -469380.24
D35: TOTAL | E35: =SUM(E24:E34) -> 643 | F35: =SUM(F24:F34) -> 7629.44 | G35: =SUM(G24:G34) -> 152.54 | H35: =SUM(H24:H34) -> 1830.48
A38: TOP 20 CLEANUP CANDIDATES BY MONTHLY COST (excl. Active prod)
A39: Rank | B39: Project | C39: Dataset | D39: Tranche | E39: Priority | F39: Size (GB) | G39: Monthly $ | H39: Annual $
A40: 1 | B40: {=INDEX('BQ-added-Data'!$A:$A,MATCH(LARGE('BQ-added-Data'!#REF!-ROW('BQ-added-Data'!#REF!)/10^10,$A40),'BQ-added-Data'!#REF!-ROW('BQ-added-Data'!#REF!)/10^10,0)+1)} -> #REF! | C40: {=INDEX('BQ-added-Data'!$C:$C,MATCH(LARGE('BQ-added-Data'!#REF!-ROW('BQ-added-Data'!#REF!)/10^10,$A40),'BQ-added-Data'!#REF!-ROW('BQ-added-Data'!#REF!)/10^10,0)+1)} -> #REF! | D40: {=INDEX('BQ-added-Data'!$G:$G,MATCH(LARGE('BQ-added-Data'!#REF!-ROW('BQ-added-Data'!#REF!)/10^10,$A40),'BQ-added-Data'!#REF!-ROW('BQ-added-Data'!#REF!)/10^10,0)+1)} -> #REF! | E40: {=INDEX('BQ-added-Data'!$H:$H,MATCH(LARGE('BQ-added-Data'!#REF!-ROW('BQ-added-Data'!#REF!)/10^10,$A40),'BQ-added-Data'!#REF!-ROW('BQ-added-Data'!#REF!)/10^10,0)+1)} -> #REF! | F40: {=INDEX('BQ-added-Data'!$E:$E,MATCH(LARGE('BQ-added-Data'!#REF!-ROW('BQ-added-Data'!#REF!)/10^10,$A40),'BQ-added-Data'!#REF!-ROW('BQ-added-Data'!#REF!)/10^10,0)+1)} -> #REF! | G40: {=INDEX('BQ-added-Data'!$F:$F,MATCH(LARGE('BQ-added-Data'!#REF!-ROW('BQ-added-Data'!#REF!)/10^10,$A40),'BQ-added-Data'!#REF!-ROW('BQ-added-Data'!#REF!)/10^10,0)+1)} -> #REF! | H40: =G40*12 -> #REF!
A41: 2 | B41: {=INDEX('BQ-added-Data'!$A:$A,MATCH(LARGE('BQ-added-Data'!#REF!-ROW('BQ-added-Data'!#REF!)/10^10,$A41),'BQ-added-Data'!#REF!-ROW('BQ-added-Data'!#REF!)/10^10,0)+1)} -> #REF! | C41: {=INDEX('BQ-added-Data'!$C:$C,MATCH(LARGE('BQ-added-Data'!#REF!-ROW('BQ-added-Data'!#REF!)/10^10,$A41),'BQ-added-Data'!#REF!-ROW('BQ-added-Data'!#REF!)/10^10,0)+1)} -> #REF! | D41: {=INDEX('BQ-added-Data'!$G:$G,MATCH(LARGE('BQ-added-Data'!#REF!-ROW('BQ-added-Data'!#REF!)/10^10,$A41),'BQ-added-Data'!#REF!-ROW('BQ-added-Data'!#REF!)/10^10,0)+1)} -> #REF! | E41: {=INDEX('BQ-added-Data'!$H:$H,MATCH(LARGE('BQ-added-Data'!#REF!-ROW('BQ-added-Data'!#REF!)/10^10,$A41),'BQ-added-Data'!#REF!-ROW('BQ-added-Data'!#REF!)/10^10,0)+1)} -> #REF! | F41: {=INDEX('BQ-added-Data'!$E:$E,MATCH(LARGE('BQ-added-Data'!#REF!-ROW('BQ-added-Data'!#REF!)/10^10,$A41),'BQ-added-Data'!#REF!-ROW('BQ-added-Data'!#REF!)/10^10,0)+1)} -> #REF! | G41: {=INDEX('BQ-added-Data'!$F:$F,MATCH(LARGE('BQ-added-Data'!#REF!-ROW('BQ-added-Data'!#REF!)/10^10,$A41),'BQ-added-Data'!#REF!-ROW('BQ-added-Data'!#REF!)/10^10,0)+1)} -> #REF! | H41: =G41*12 -> #REF!
A42: 3 | B42: {=INDEX('BQ-added-Data'!$A:$A,MATCH(LARGE('BQ-added-Data'!#REF!-ROW('BQ-added-Data'!#REF!)/10^10,$A42),'BQ-added-Data'!#REF!-ROW('BQ-added-Data'!#REF!)/10^10,0)+1)} -> #REF! | C42: {=INDEX('BQ-added-Data'!$C:$C,MATCH(LARGE('BQ-added-Data'!#REF!-ROW('BQ-added-Data'!#REF!)/10^10,$A42),'BQ-added-Data'!#REF!-ROW('BQ-added-Data'!#REF!)/10^10,0)+1)} -> #REF! | D42: {=INDEX('BQ-added-Data'!$G:$G,MATCH(LARGE('BQ-added-Data'!#REF!-ROW('BQ-added-Data'!#REF!)/10^10,$A42),'BQ-added-Data'!#REF!-ROW('BQ-added-Data'!#REF!)/10^10,0)+1)} -> #REF! | E42: {=INDEX('BQ-added-Data'!$H:$H,MATCH(LARGE('BQ-added-Data'!#REF!-ROW('BQ-added-Data'!#REF!)/10^10,$A42),'BQ-added-Data'!#REF!-ROW('BQ-added-Data'!#REF!)/10^10,0)+1)} -> #REF! | F42: {=INDEX('BQ-added-Data'!$E:$E,MATCH(LARGE('BQ-added-Data'!#REF!-ROW('BQ-added-Data'!#REF!)/10^10,$A42),'BQ-added-Data'!#REF!-ROW('BQ-added-Data'!#REF!)/10^10,0)+1)} -> #REF! | G42: {=INDEX('BQ-added-Data'!$F:$F,MATCH(LARGE('BQ-added-Data'!#REF!-ROW('BQ-added-Data'!#REF!)/10^10,$A42),'BQ-added-Data'!#REF!-ROW('BQ-added-Data'!#REF!)/10^10,0)+1)} -> #REF! | H42: =G42*12 -> #REF!
A43: 4 | B43: {=INDEX('BQ-added-Data'!$A:$A,MATCH(LARGE('BQ-added-Data'!#REF!-ROW('BQ-added-Data'!#REF!)/10^10,$A43),'BQ-added-Data'!#REF!-ROW('BQ-added-Data'!#REF!)/10^10,0)+1)} -> #REF! | C43: {=INDEX('BQ-added-Data'!$C:$C,MATCH(LARGE('BQ-added-Data'!#REF!-ROW('BQ-added-Data'!#REF!)/10^10,$A43),'BQ-added-Data'!#REF!-ROW('BQ-added-Data'!#REF!)/10^10,0)+1)} -> #REF! | D43: {=INDEX('BQ-added-Data'!$G:$G,MATCH(LARGE('BQ-added-Data'!#REF!-ROW('BQ-added-Data'!#REF!)/10^10,$A43),'BQ-added-Data'!#REF!-ROW('BQ-added-Data'!#REF!)/10^10,0)+1)} -> #REF! | E43: {=INDEX('BQ-added-Data'!$H:$H,MATCH(LARGE('BQ-added-Data'!#REF!-ROW('BQ-added-Data'!#REF!)/10^10,$A43),'BQ-added-Data'!#REF!-ROW('BQ-added-Data'!#REF!)/10^10,0)+1)} -> #REF! | F43: {=INDEX('BQ-added-Data'!$E:$E,MATCH(LARGE('BQ-added-Data'!#REF!-ROW('BQ-added-Data'!#REF!)/10^10,$A43),'BQ-added-Data'!#REF!-ROW('BQ-added-Data'!#REF!)/10^10,0)+1)} -> #REF! | G43: {=INDEX('BQ-added-Data'!$F:$F,MATCH(LARGE('BQ-added-Data'!#REF!-ROW('BQ-added-Data'!#REF!)/10^10,$A43),'BQ-added-Data'!#REF!-ROW('BQ-added-Data'!#REF!)/10^10,0)+1)} -> #REF! | H43: =G43*12 -> #REF!
...

Sheet BigQuery
A1: Organisation | B1: Project | C1: Dataset | D1: Deletion Reason | E1: Tables | F1: Total GB | G1: Monthly Saving ($) | H1: Action | I1: Validation SQL (Storage) | J1: Validation SQL (Read/Usage) | K1: Decision | L1: Decision Notes
A2: thehutgroup.com | B2: vibrant-map-107910 | C2: bigquery_pipeline_manager | D2: Stale Production: Idle 460 days. | E2: 6549 | F2: 105879.22 | G2: 2117.58 | H2: DROP DATASET vibrant-map-107910.bigquery_pipeline_manager | I2: SELECT COUNT(*), SUM(total_logical_bytes)/1024/1024/1024 as gb, MAX(storage_last_modified_time) FROM `vibrant-map-107910.region-eu.INFORMATION_SCHEMA.TABLE_STORAGE` WHERE table_schema = 'bigquery_pipeline_manager' | J2: SELECT job_id, user_email FROM `vibrant-map-107910.region-eu.INFORMATION_SCHEMA.JOBS_BY_PROJECT` WHERE creation_time > TIMESTAMP_SUB(CURRENT_TIMESTAMP(), INTERVAL 180 DAY) AND (destination_table.dataset_id = 'bigquery_pipeline_manager' OR EXISTS(SELECT 1 FROM UNNEST(referenced_tables) ref WHERE ref.dataset_id = 'bigquery_pipeline_manager')) LIMIT 1 | K2: {=_xlfn.IFS(OR($C2="abtest_results",$C2="experimentation_sessions_colour_swatch"),"DROP CONFIRMED",OR($B2="thg-influencer",$B2="thg-ingenuity",$B2="thg-central-marketing",$B2="thg-seoclarity"),"HOLD",TRUE,"REVIEW")} -> REVIEW | L2: {=_xlfn.IFS(OR($C2="abtest_results",$C2="experimentation_sessions_colour_swatch"),"Experimentation team — unused, deprecated format. Safe to drop.",OR($B2="thg-influencer",$B2="thg-ingenuity",$B2="thg-central-marketing",$B2="thg-seoclarity"),"HOLD — Charlie Stringer to review before deletion",TRUE,"")}
A3: thehutgroup.com | B3: agile-bonbon-662 | C3: 94144777 | D3: Stale Production: Idle 721 days. | E3: 4627 | F3: 65273.34 | G3: 1305.47 | H3: DROP DATASET agile-bonbon-662.94144777 | I3: SELECT COUNT(*), SUM(total_logical_bytes)/1024/1024/1024 as gb, MAX(storage_last_modified_time) FROM `agile-bonbon-662.region-eu.INFORMATION_SCHEMA.TABLE_STORAGE` WHERE table_schema = '94144777' | J3: SELECT job_id, user_email FROM `agile-bonbon-662.region-eu.INFORMATION_SCHEMA.JOBS_BY_PROJECT` WHERE creation_time > TIMESTAMP_SUB(CURRENT_TIMESTAMP(), INTERVAL 180 DAY) AND (destination_table.dataset_id = '94144777' OR EXISTS(SELECT 1 FROM UNNEST(referenced_tables) ref WHERE ref.dataset_id = '94144777')) LIMIT 1 | K3: {=_xlfn.IFS(OR($C3="abtest_results",$C3="experimentation_sessions_colour_swatch"),"DROP CONFIRMED",OR($B3="thg-influencer",$B3="thg-ingenuity",$B3="thg-central-marketing",$B3="thg-seoclarity"),"HOLD",TRUE,"REVIEW")} -> REVIEW | L3: {=_xlfn.IFS(OR($C3="abtest_results",$C3="experimentation_sessions_colour_swatch"),"Experimentation team — unused, deprecated format. Safe to drop.",OR($B3="thg-influencer",$B3="thg-ingenuity",$B3="thg-central-marketing",$B3="thg-seoclarity"),"HOLD — Charlie Stringer to review before deletion",TRUE,"")}
A4: thehutgroup.com | B4: the-hut-group | C4: abtest_results | D4: Expired Experiment: Idle 488 days. | E4: 37993 | F4: 21960.2 | G4: 439.2 | H4: DROP DATASET the-hut-group.abtest_results | I4: SELECT COUNT(*), SUM(total_logical_bytes)/1024/1024/1024 as gb, MAX(storage_last_modified_time) FROM `the-hut-group.region-eu.INFORMATION_SCHEMA.TABLE_STORAGE` WHERE table_schema = 'abtest_results' | J4: SELECT job_id, user_email FROM `the-hut-group.region-eu.INFORMATION_SCHEMA.JOBS_BY_PROJECT` WHERE creation_time > TIMESTAMP_SUB(CURRENT_TIMESTAMP(), INTERVAL 180 DAY) AND (destination_table.dataset_id = 'abtest_results' OR EXISTS(SELECT 1 FROM UNNEST(referenced_tables) ref WHERE ref.dataset_id = 'abtest_results')) LIMIT 1 | K4: {=_xlfn.IFS(OR($C4="abtest_results",$C4="experimentation_sessions_colour_swatch"),"DROP CONFIRMED",OR($B4="thg-influencer",$B4="thg-ingenuity",$B4="thg-central-marketing",$B4="thg-seoclarity"),"HOLD",TRUE,"REVIEW")} -> DROP CONFIRMED | L4: {=_xlfn.IFS(OR($C4="abtest_results",$C4="experimentation_sessions_colour_swatch"),"Experimentation team — unused, deprecated format. Safe to drop.",OR($B4="thg-influencer",$B4="thg-ingenuity",$B4="thg-central-marketing",$B4="thg-seoclarity"),"HOLD — Charlie Stringer to review before deletion",TRUE,"")} -> Experimentation team — unused, deprecated format. Safe to drop.
A5: thehutgroup.com | B5: agile-bonbon-662 | C5: SessionsAllSites | D5: Stale Production: Idle 2516 days. | E5: 1960 | F5: 21579.93 | G5: 431.6 | H5: DROP DATASET agile-bonbon-662.SessionsAllSites | I5: SELECT COUNT(*), SUM(total_logical_bytes)/1024/1024/1024 as gb, MAX(storage_last_modified_time) FROM `agile-bonbon-662.region-eu.INFORMATION_SCHEMA.TABLE_STORAGE` WHERE table_schema = 'SessionsAllSites' | J5: SELECT job_id, user_email FROM `agile-bonbon-662.region-eu.INFORMATION_SCHEMA.JOBS_BY_PROJECT` WHERE creation_time > TIMESTAMP_SUB(CURRENT_TIMESTAMP(), INTERVAL 180 DAY) AND (destination_table.dataset_id = 'SessionsAllSites' OR EXISTS(SELECT 1 FROM UNNEST(referenced_tables) ref WHERE ref.dataset_id = 'SessionsAllSites')) LIMIT 1 | K5: {=_xlfn.IFS(OR($C5="abtest_results",$C5="experimentation_sessions_colour_swatch"),"DROP CONFIRMED",OR($B5="thg-influencer",$B5="thg-ingenuity",$B5="thg-central-marketing",$B5="thg-seoclarity"),"HOLD",TRUE,"REVIEW")} -> REVIEW | L5: {=_xlfn.IFS(OR($C5="abtest_results",$C5="experimentation_sessions_colour_swatch"),"Experimentation team — unused, deprecated format. Safe to drop.",OR($B5="thg-influencer",$B5="thg-ingenuity",$B5="thg-central-marketing",$B5="thg-seoclarity"),"HOLD — Charlie Stringer to review before deletion",TRUE,"")}
A6: thehutgroup.com | B6: agile-bonbon-662 | C6: US_Data | D6: Stale Production: Idle 1964 days. | E6: 5210 | F6: 20085.74 | G6: 401.71 | H6: DROP DATASET agile-bonbon-662.US_Data | I6: SELECT COUNT(*), SUM(total_logical_bytes)/1024/1024/1024 as gb, MAX(storage_last_modified_time) FROM `agile-bonbon-662.region-eu.INFORMATION_SCHEMA.TABLE_STORAGE` WHERE table_schema = 'US_Data' | J6: SELECT job_id, user_email FROM `agile-bonbon-662.region-eu.INFORMATION_SCHEMA.JOBS_BY_PROJECT` WHERE creation_time > TIMESTAMP_SUB(CURRENT_TIMESTAMP(), INTERVAL 180 DAY) AND (destination_table.dataset_id = 'US_Data' OR EXISTS(SELECT 1 FROM UNNEST(referenced_tables) ref WHERE ref.dataset_id = 'US_Data')) LIMIT 1 | K6: {=_xlfn.IFS(OR($C6="abtest_results",$C6="experimentation_sessions_colour_swatch"),"DROP CONFIRMED",OR($B6="thg-influencer",$B6="thg-ingenuity",$B6="thg-central-marketing",$B6="thg-seoclarity"),"HOLD",TRUE,"REVIEW")} -> REVIEW | L6: {=_xlfn.IFS(OR($C6="abtest_results",$C6="experimentation_sessions_colour_swatch"),"Experimentation team — unused, deprecated format. Safe to drop.",OR($B6="thg-influencer",$B6="thg-ingenuity",$B6="thg-central-marketing",$B6="thg-seoclarity"),"HOLD — Charlie Stringer to review before deletion",TRUE,"")}
A7: thehutgroup.com | B7: the-hut-group | C7: metrics | D7: Stale Production: Idle 1456 days. | E7: 3672 | F7: 18031.47 | G7: 360.63 | H7: DROP DATASET the-hut-group.metrics | I7: SELECT COUNT(*), SUM(total_logical_bytes)/1024/1024/1024 as gb, MAX(storage_last_modified_time) FROM `the-hut-group.region-eu.INFORMATION_SCHEMA.TABLE_STORAGE` WHERE table_schema = 'metrics' | J7: SELECT job_id, user_email FROM `the-hut-group.region-eu.INFORMATION_SCHEMA.JOBS_BY_PROJECT` WHERE creation_time > TIMESTAMP_SUB(CURRENT_TIMESTAMP(), INTERVAL 180 DAY) AND (destination_table.dataset_id = 'metrics' OR EXISTS(SELECT 1 FROM UNNEST(referenced_tables) ref WHERE ref.dataset_id = 'metrics')) LIMIT 1 | K7: {=_xlfn.IFS(OR($C7="abtest_results",$C7="experimentation_sessions_colour_swatch"),"DROP CONFIRMED",OR($B7="thg-influencer",$B7="thg-ingenuity",$B7="thg-central-marketing",$B7="thg-seoclarity"),"HOLD",TRUE,"REVIEW")} -> REVIEW | L7: {=_xlfn.IFS(OR($C7="abtest_results",$C7="experimentation_sessions_colour_swatch"),"Experimentation team — unused, deprecated format. Safe to drop.",OR($B7="thg-influencer",$B7="thg-ingenuity",$B7="thg-central-marketing",$B7="thg-seoclarity"),"HOLD — Charlie Stringer to review before deletion",TRUE,"")}
A8: thehutgroup.com | B8: agile-bonbon-662 | C8: 18809831 | D8: Stale Production: Idle 721 days. | E8: 3834 | F8: 17344.72 | G8: 346.89 | H8: DROP DATASET agile-bonbon-662.18809831 | I8: SELECT COUNT(*), SUM(total_logical_bytes)/1024/1024/1024 as gb, MAX(storage_last_modified_time) FROM `agile-bonbon-662.region-eu.INFORMATION_SCHEMA.TABLE_STORAGE` WHERE table_schema = '18809831' | J8: SELECT job_id, user_email FROM `agile-bonbon-662.region-eu.INFORMATION_SCHEMA.JOBS_BY_PROJECT` WHERE creation_time > TIMESTAMP_SUB(CURRENT_TIMESTAMP(), INTERVAL 180 DAY) AND (destination_table.dataset_id = '18809831' OR EXISTS(SELECT 1 FROM UNNEST(referenced_tables) ref WHERE ref.dataset_id = '18809831')) LIMIT 1 | K8: {=_xlfn.IFS(OR($C8="abtest_results",$C8="experimentation_sessions_colour_swatch"),"DROP CONFIRMED",OR($B8="thg-influencer",$B8="thg-ingenuity",$B8="thg-central-marketing",$B8="thg-seoclarity"),"HOLD",TRUE,"REVIEW")} -> REVIEW | L8: {=_xlfn.IFS(OR($C8="abtest_results",$C8="experimentation_sessions_colour_swatch"),"Experimentation team — unused, deprecated format. Safe to drop.",OR($B8="thg-influencer",$B8="thg-ingenuity",$B8="thg-central-marketing",$B8="thg-seoclarity"),"HOLD — Charlie Stringer to review before deletion",TRUE,"")}
A9: thehutgroup.com | B9: agile-bonbon-662 | C9: 88617117 | D9: Stale Production: Idle 721 days. | E9: 1231 | F9: 15588.53 | G9: 311.77 | H9: DROP DATASET agile-bonbon-662.88617117 | I9: SELECT COUNT(*), SUM(total_logical_bytes)/1024/1024/1024 as gb, MAX(storage_last_modified_time) FROM `agile-bonbon-662.region-eu.INFORMATION_SCHEMA.TABLE_STORAGE` WHERE table_schema = '88617117' | J9: SELECT job_id, user_email FROM `agile-bonbon-662.region-eu.INFORMATION_SCHEMA.JOBS_BY_PROJECT` WHERE creation_time > TIMESTAMP_SUB(CURRENT_TIMESTAMP(), INTERVAL 180 DAY) AND (destination_table.dataset_id = '88617117' OR EXISTS(SELECT 1 FROM UNNEST(referenced_tables) ref WHERE ref.dataset_id = '88617117')) LIMIT 1 | K9: {=_xlfn.IFS(OR($C9="abtest_results",$C9="experimentation_sessions_colour_swatch"),"DROP CONFIRMED",OR($B9="thg-influencer",$B9="thg-ingenuity",$B9="thg-central-marketing",$B9="thg-seoclarity"),"HOLD",TRUE,"REVIEW")} -> REVIEW | L9: {=_xlfn.IFS(OR($C9="abtest_results",$C9="experimentation_sessions_colour_swatch"),"Experimentation team — unused, deprecated format. Safe to drop.",OR($B9="thg-influencer",$B9="thg-ingenuity",$B9="thg-central-marketing",$B9="thg-seoclarity"),"HOLD — Charlie Stringer to review before deletion",TRUE,"")}
A10: thehutgroup.com | B10: agile-bonbon-662 | C10: 773825 | D10: Stale Production: Idle 721 days. | E10: 3837 | F10: 11641.81 | G10: 232.84 | H10: DROP DATASET agile-bonbon-662.773825 | I10: SELECT COUNT(*), SUM(total_logical_bytes)/1024/1024/1024 as gb, MAX(storage_last_modified_time) FROM `agile-bonbon-662.region-eu.INFORMATION_SCHEMA.TABLE_STORAGE` WHERE table_schema = '773825' | J10: SELECT job_id, user_email FROM `agile-bonbon-662.region-eu.INFORMATION_SCHEMA.JOBS_BY_PROJECT` WHERE creation_time > TIMESTAMP_SUB(CURRENT_TIMESTAMP(), INTERVAL 180 DAY) AND (destination_table.dataset_id = '773825' OR EXISTS(SELECT 1 FROM UNNEST(referenced_tables) ref WHERE ref.dataset_id = '773825')) LIMIT 1 | K10: {=_xlfn.IFS(OR($C10="abtest_results",$C10="experimentation_sessions_colour_swatch"),"DROP CONFIRMED",OR($B10="thg-influencer",$B10="thg-ingenuity",$B10="thg-central-marketing",$B10="thg-seoclarity"),"HOLD",TRUE,"REVIEW")} -> REVIEW | L10: {=_xlfn.IFS(OR($C10="abtest_results",$C10="experimentation_sessions_colour_swatch"),"Experimentation team — unused, deprecated format. Safe to drop.",OR($B10="thg-influencer",$B10="thg-ingenuity",$B10="thg-central-marketing",$B10="thg-seoclarity"),"HOLD — Charlie Stringer to review before deletion",TRUE,"")}
A11: thehutgroup.com | B11: agile-bonbon-662 | C11: SA360_ML_Ad_Copy | D11: Stale Production: Idle 750 days. | E11: 260 | F11: 11047.96 | G11: 220.96 | H11: DROP DATASET agile-bonbon-662.SA360_ML_Ad_Copy | I11: SELECT COUNT(*), SUM(total_logical_bytes)/1024/1024/1024 as gb, MAX(storage_last_modified_time) FROM `agile-bonbon-662.region-eu.INFORMATION_SCHEMA.TABLE_STORAGE` WHERE table_schema = 'SA360_ML_Ad_Copy' | J11: SELECT job_id, user_email FROM `agile-bonbon-662.region-eu.INFORMATION_SCHEMA.JOBS_BY_PROJECT` WHERE creation_time > TIMESTAMP_SUB(CURRENT_TIMESTAMP(), INTERVAL 180 DAY) AND (destination_table.dataset_id = 'SA360_ML_Ad_Copy' OR EXISTS(SELECT 1 FROM UNNEST(referenced_tables) ref WHERE ref.dataset_id = 'SA360_ML_Ad_Copy')) LIMIT 1 | K11: {=_xlfn.IFS(OR($C11="abtest_results",$C11="experimentation_sessions_colour_swatch"),"DROP CONFIRMED",OR($B11="thg-influencer",$B11="thg-ingenuity",$B11="thg-central-marketing",$B11="thg-seoclarity"),"HOLD",TRUE,"REVIEW")} -> REVIEW | L11: {=_xlfn.IFS(OR($C11="abtest_results",$C11="experimentation_sessions_colour_swatch"),"Experimentation team — unused, deprecated format. Safe to drop.",OR($B11="thg-influencer",$B11="thg-ingenuity",$B11="thg-central-marketing",$B11="thg-seoclarity"),"HOLD — Charlie Stringer to review before deletion",TRUE,"")}
A12: thehutgroup.com | B12: the-hut-group | C12: archived_unity | D12: Abandoned Archive: Idle 1963 days. | E12: 335 | F12: 10315.79 | G12: 206.32 | H12: DROP DATASET the-hut-group.archived_unity | I12: SELECT COUNT(*), SUM(total_logical_bytes)/1024/1024/1024 as gb, MAX(storage_last_modified_time) FROM `the-hut-group.region-eu.INFORMATION_SCHEMA.TABLE_STORAGE` WHERE table_schema = 'archived_unity' | J12: SELECT job_id, user_email FROM `the-hut-group.region-eu.INFORMATION_SCHEMA.JOBS_BY_PROJECT` WHERE creation_time > TIMESTAMP_SUB(CURRENT_TIMESTAMP(), INTERVAL 180 DAY) AND (destination_table.dataset_id = 'archived_unity' OR EXISTS(SELECT 1 FROM UNNEST(referenced_tables) ref WHERE ref.dataset_id = 'archived_unity')) LIMIT 1 | K12: {=_xlfn.IFS(OR($C12="abtest_results",$C12="experimentation_sessions_colour_swatch"),"DROP CONFIRMED",OR($B12="thg-influencer",$B12="thg-ingenuity",$B12="thg-central-marketing",$B12="thg-seoclarity"),"HOLD",TRUE,"REVIEW")} -> REVIEW | L12: {=_xlfn.IFS(OR($C12="abtest_results",$C12="experimentation_sessions_colour_swatch"),"Experimentation team — unused, deprecated format. Safe to drop.",OR($B12="thg-influencer",$B12="thg-ingenuity",$B12="thg-central-marketing",$B12="thg-seoclarity"),"HOLD — Charlie Stringer to review before deletion",TRUE,"")}
A13: thehutgroup.com | B13: the-hut-group | C13: segmentation | D13: Stale Production: Idle 1964 days. | E13: 5360 | F13: 8843.08 | G13: 176.86 | H13: DROP DATASET the-hut-group.segmentation | I13: SELECT COUNT(*), SUM(total_logical_bytes)/1024/1024/1024 as gb, MAX(storage_last_modified_time) FROM `the-hut-group.region-eu.INFORMATION_SCHEMA.TABLE_STORAGE` WHERE table_schema = 'segmentation' | J13: SELECT job_id, user_email FROM `the-hut-group.region-eu.INFORMATION_SCHEMA.JOBS_BY_PROJECT` WHERE creation_time > TIMESTAMP_SUB(CURRENT_TIMESTAMP(), INTERVAL 180 DAY) AND (destination_table.dataset_id = 'segmentation' OR EXISTS(SELECT 1 FROM UNNEST(referenced_tables) ref WHERE ref.dataset_id = 'segmentation')) LIMIT 1 | K13: {=_xlfn.IFS(OR($C13="abtest_results",$C13="experimentation_sessions_colour_swatch"),"DROP CONFIRMED",OR($B13="thg-influencer",$B13="thg-ingenuity",$B13="thg-central-marketing",$B13="thg-seoclarity"),"HOLD",TRUE,"REVIEW")} -> REVIEW | L13: {=_xlfn.IFS(OR($C13="abtest_results",$C13="experimentation_sessions_colour_swatch"),"Experimentation team — unused, deprecated format. Safe to drop.",OR($B13="thg-influencer",$B13="thg-ingenuity",$B13="thg-central-marketing",$B13="thg-seoclarity"),"HOLD — Charlie Stringer to review before deletion",TRUE,"")}
... A334: thehutgroup.com | B334: agile-bonbon-662 | C334: analytics_294922532 | D334: Stale Production: Idle 815 days. | E334: 531 | F334: 10.55 | G334: 0.21 | H334: DROP DATASET agile-bonbon-662.analytics_294922532 | I334: SELECT COUNT(*), SUM(total_logical_bytes)/1024/1024/1024 as gb, MAX(storage_last_modified_time) FROM `agile-bonbon-662.region-eu.INFORMATION_SCHEMA.TABLE_STORAGE` WHERE table_schema = 'analytics_294922532' | J334: SELECT job_id, user_email FROM `agile-bonbon-662.region-eu.INFORMATION_SCHEMA.JOBS_BY_PROJECT` WHERE creation_time > TIMESTAMP_SUB(CURRENT_TIMESTAMP(), INTERVAL 180 DAY) AND (destination_table.dataset_id = 'analytics_294922532' OR EXISTS(SELECT 1 FROM UNNEST(referenced_tables) ref WHERE ref.dataset_id = 'analytics_294922532')) LIMIT 1 | K334: {=_xlfn.IFS(OR($C334="abtest_results",$C334="experimentation_sessions_colour_swatch"),"DROP CONFIRMED",OR($B334="thg-influencer",$B334="thg-ingenuity",$B334="thg-central-marketing",$B334="thg-seoclarity"),"HOLD",TRUE,"REVIEW")} -> REVIEW | L334: {=_xlfn.IFS(OR($C334="abtest_results",$C334="experimentation_sessions_colour_swatch"),"Experimentation team — unused, deprecated format. Safe to drop.",OR($B334="thg-influencer",$B334="thg-ingenuity",$B334="thg-central-marketing",$B334="thg-seoclarity"),"HOLD — Charlie Stringer to review before deletion",TRUE,"")}

Sheet BQ-added-Data
A1: Project | B1: Region | C1: Dataset | D1: Description | E1: Size (GB) | F1: Monthly Cost ($) | G1: Tranche | H1: Cleanup Priority | I1: Days Since Last Activity | J1: Days Since Last Modified | K1: Last Read Time | L1: Last Write Time | M1: Last 5 Reads (Who/When) | N1: Last 5 Writes (Who/When) | O1: Last Storage Update | P1: Defensible Deletion Status | Q1: Decision | R1: Decision Notes | S1: Original Defensible Deletion Status
A2: thg-beauty | B2: eu | C2: Commercial_Marketing | D2: No Description | E2: 13280.86 | F2: 265.62 | G2: Active | H2: Low | I2: 0 | J2: 0 | K2: 46197.42 | L2: 46197.241 | M2: 2026-06-24 10:04 (beauty-data@agile-bonbon-662.iam.gserviceaccount.com) 2026-06-24 10:04 (beauty-data@agile-bonbon-662.iam.gserviceaccount.com) 2026-06-24 10:04 (beauty-data@agile-bonbon-662.iam.gserviceaccount.com) 2026-06-24 10:01 (beauty-data@agile-bonbon-662.iam.gserviceaccount.com) 2026-06-24 07:06 (beauty-data@agile-bonbon-662.iam.gserviceaccount.com) | N2: 2026-06-24 05:47 (beauty-data@agile-bonbon-662.iam.gserviceaccount.com) 2026-06-24 05:46 (beauty-data@agile-bonbon-662.iam.gserviceaccount.com) 2026-06-24 05:46 (beauty-data@agile-bonbon-662.iam.gserviceaccount.com) 2026-06-24 05:46 (beauty-data@agile-bonbon-662.iam.gserviceaccount.com) 2026-06-24 05:16 (sa-bpswcbdsql01@thg-beauty.iam.gserviceaccount.com) | O2: 46197.241 | P2: =IF($Q2="DELETE",IF($S2="CONFIRMED: NO MODS > 1YR","CONFIRMED: NO MODS > 1YR","DO NOT DELETE — not defensibly confirmed"),IF($Q2="HOLD","DO NOT DELETE — HOLD (Charlie review)",IF($Q2="KEEP","DO NOT DELETE — KEEP",IF(ISNUMBER(SEARCH("REVIEW",$Q2)),"DO NOT DELETE — REVIEW pending",$S2)))) -> CONFIRMED: NO MODS > 1YR | Q2: {=_xlfn.IFS(AND($A2="thg-beauty",ISNUMBER(SEARCH("liveramp",$C2))),"DELETE",$A2="agile-bonbon-662",_xlfn.IFS(LEFT($G2,9)="Tranche 1","DELETE",$C2="Sessions_Level_1_All_Sites","KEEP",ISNUMBER(--$C2),"REVIEW — UA raw logs",$C2="Emag_Reporting","KEEP",$C2="Nutrition_Data_Archived_Tables","KEEP",$C2="EU_Data","KEEP",TRUE,"REVIEW"),OR($A2="thg-influencer",$A2="thg-ingenuity",$A2="thg-central-marketing",$A2="thg-seoclarity"),"HOLD",TRUE,"")} | R2: {=_xlfn.IFS(AND($A2="thg-beauty",ISNUMBER(SEARCH("liveramp",$C2))),"thg-beauty Liveramp dataset — confirmed safe to delete",$A2="agile-bonbon-662",_xlfn.IFS(LEFT($G2,9)="Tranche 1","Tranche 1: cleared",$C2="Sessions_Level_1_All_Sites","Downstream aggregation of UA raw logs — keep if raw tables go",ISNUMBER(--$C2),"UA raw site logs (account ID) — keep pending audit-retention check",$C2="Emag_Reporting","Legacy but likely needed",$C2="Nutrition_Data_Archived_Tables","Worth keeping",$C2="EU_Data","Static lookup tables — scripts still reference (smoke-test risk)",TRUE,"Review"),OR($A2="thg-influencer",$A2="thg-ingenuity",$A2="thg-central-marketing",$A2="thg-seoclarity"),"HOLD — Charlie Stringer to review before deletion",TRUE,"")} | S2: CONFIRMED: NO MODS > 1YR
A3: thg-beauty | B3: eu | C3: Site_Reporting | D3: No Description | E3: 6902.77 | F3: 138.06 | G3: Active | H3: Low | I3: 0 | J3: 0 | K3: 46197.446 | L3: 46197.437 | M3: 2026-06-24 10:42 (vy.nguyen12@thehutgroup.com) 2026-06-24 10:41 (vy.nguyen12@thehutgroup.com) 2026-06-24 10:37 (vy.nguyen12@thehutgroup.com) 2026-06-24 10:36 (vy.nguyen12@thehutgroup.com) 2026-06-24 10:36 (vy.nguyen12@thehutgroup.com) | N3: 2026-06-24 10:28 (sa-bpswcbdsql01@thg-beauty.iam.gserviceaccount.com) 2026-06-24 10:28 (sa-bpswcbdsql01@thg-beauty.iam.gserviceaccount.com) 2026-06-24 10:28 (sa-bpswcbdsql01@thg-beauty.iam.gserviceaccount.com) 2026-06-24 10:27 (sa-bpswcbdsql01@thg-beauty.iam.gserviceaccount.com) 2026-06-24 10:27 (sa-bpswcbdsql01@thg-beauty.iam.gserviceaccount.com) | O3: 46197.44 | P3: =IF($Q3="DELETE",IF($S3="CONFIRMED: NO MODS > 1YR","CONFIRMED: NO MODS > 1YR","DO NOT DELETE — not defensibly confirmed"),IF($Q3="HOLD","DO NOT DELETE — HOLD (Charlie review)",IF($Q3="KEEP","DO NOT DELETE — KEEP",IF(ISNUMBER(SEARCH("REVIEW",$Q3)),"DO NOT DELETE — REVIEW pending",$S3)))) -> CONFIRMED: NO MODS > 1YR | Q3: {=_xlfn.IFS(AND($A3="thg-beauty",ISNUMBER(SEARCH("liveramp",$C3))),"DELETE",$A3="agile-bonbon-662",_xlfn.IFS(LEFT($G3,9)="Tranche 1","DELETE",$C3="Sessions_Level_1_All_Sites","KEEP",ISNUMBER(--$C3),"REVIEW — UA raw logs",$C3="Emag_Reporting","KEEP",$C3="Nutrition_Data_Archived_Tables","KEEP",$C3="EU_Data","KEEP",TRUE,"REVIEW"),OR($A3="thg-influencer",$A3="thg-ingenuity",$A3="thg-central-marketing",$A3="thg-seoclarity"),"HOLD",TRUE,"")} | R3: {=_xlfn.IFS(AND($A3="thg-beauty",ISNUMBER(SEARCH("liveramp",$C3))),"thg-beauty Liveramp dataset — confirmed safe to delete",$A3="agile-bonbon-662",_xlfn.IFS(LEFT($G3,9)="Tranche 1","Tranche 1: cleared",$C3="Sessions_Level_1_All_Sites","Downstream aggregation of UA raw logs — keep if raw tables go",ISNUMBER(--$C3),"UA raw site logs (account ID) — keep pending audit-retention check",$C3="Emag_Reporting","Legacy but likely needed",$C3="Nutrition_Data_Archived_Tables","Worth keeping",$C3="EU_Data","Static lookup tables — scripts still reference (smoke-test risk)",TRUE,"Review"),OR($A3="thg-influencer",$A3="thg-ingenuity",$A3="thg-central-marketing",$A3="thg-seoclarity"),"HOLD — Charlie Stringer to review before deletion",TRUE,"")} | S3: CONFIRMED: NO MODS > 1YR
A4: thg-beauty | B4: eu | C4: beauty_email | D4: No Description | E4: 4983.25 | F4: 99.66 | G4: Active | H4: Low | I4: 0 | J4: 0 | K4: 46197.403 | L4: 46197.271 | M4: 2026-06-24 09:40 (amalu.thevalakara21@thg.com) 2026-06-24 09:33 (shilpa.veedu03@thg.com) 2026-06-24 09:33 (shilpa.veedu03@thg.com) 2026-06-24 09:33 (shilpa.veedu03@thg.com) 2026-06-24 09:33 (shilpa.veedu03@thg.com) | N4: 2026-06-24 06:30 (amalu.thevalakara21@thg.com) 2026-06-24 02:39 (sa-bpswcbdsql01@thg-beauty.iam.gserviceaccount.com) 2026-06-24 02:39 (sa-bpswcbdsql01@thg-beauty.iam.gserviceaccount.com) 2026-06-24 02:39 (sa-bpswcbdsql01@thg-beauty.iam.gserviceaccount.com) 2026-06-24 02:39 (sa-bpswcbdsql01@thg-beauty.iam.gserviceaccount.com) | O4: 46197.272 | P4: =IF($Q4="DELETE",IF($S4="CONFIRMED: NO MODS > 1YR","CONFIRMED: NO MODS > 1YR","DO NOT DELETE — not defensibly confirmed"),IF($Q4="HOLD","DO NOT DELETE — HOLD (Charlie review)",IF($Q4="KEEP","DO NOT DELETE — KEEP",IF(ISNUMBER(SEARCH("REVIEW",$Q4)),"DO NOT DELETE — REVIEW pending",$S4)))) -> REVIEW | Q4: {=_xlfn.IFS(AND($A4="thg-beauty",ISNUMBER(SEARCH("liveramp",$C4))),"DELETE",$A4="agile-bonbon-662",_xlfn.IFS(LEFT($G4,9)="Tranche 1","DELETE",$C4="Sessions_Level_1_All_Sites","KEEP",ISNUMBER(--$C4),"REVIEW — UA raw logs",$C4="Emag_Reporting","KEEP",$C4="Nutrition_Data_Archived_Tables","KEEP",$C4="EU_Data","KEEP",TRUE,"REVIEW"),OR($A4="thg-influencer",$A4="thg-ingenuity",$A4="thg-central-marketing",$A4="thg-seoclarity"),"HOLD",TRUE,"")} | R4: {=_xlfn.IFS(AND($A4="thg-beauty",ISNUMBER(SEARCH("liveramp",$C4))),"thg-beauty Liveramp dataset — confirmed safe to delete",$A4="agile-bonbon-662",_xlfn.IFS(LEFT($G4,9)="Tranche 1","Tranche 1: cleared",$C4="Sessions_Level_1_All_Sites","Downstream aggregation of UA raw logs — keep if raw tables go",ISNUMBER(--$C4),"UA raw site logs (account ID) — keep pending audit-retention check",$C4="Emag_Reporting","Legacy but likely needed",$C4="Nutrition_Data_Archived_Tables","Worth keeping",$C4="EU_Data","Static lookup tables — scripts still reference (smoke-test risk)",TRUE,"Review"),OR($A4="thg-influencer",$A4="thg-ingenuity",$A4="thg-central-marketing",$A4="thg-seoclarity"),"HOLD — Charlie Stringer to review before deletion",TRUE,"")} | S4: REVIEW
A5: thg-beauty | B5: eu | C5: Merch | D5: No Description | E5: 3742.88 | F5: 74.86 | G5: Active | H5: Low | I5: 0 | J5: 0 | K5: 46197.351 | L5: 46197.326 | M5: 2026-06-24 08:25 (beauty-data@agile-bonbon-662.iam.gserviceaccount.com) 2026-06-24 08:14 (beauty-data@agile-bonbon-662.iam.gserviceaccount.com) 2026-06-24 08:14 (beauty-data@agile-bonbon-662.iam.gserviceaccount.com) 2026-06-24 08:09 (haleema.anbreen45@thg.com) 2026-06-24 08:04 (beauty-data@agile-bonbon-662.iam.gserviceaccount.com) | N5: 2026-06-24 07:49 (beauty-data@agile-bonbon-662.iam.gserviceaccount.com) 2026-06-24 07:48 (beauty-data@agile-bonbon-662.iam.gserviceaccount.com) 2026-06-24 07:48 (beauty-data@agile-bonbon-662.iam.gserviceaccount.com) 2026-06-24 07:48 (beauty-data@agile-bonbon-662.iam.gserviceaccount.com) 2026-06-24 07:45 (beauty-data@agile-bonbon-662.iam.gserviceaccount.com) | O5: 46197.326 | P5: =IF($Q5="DELETE",IF($S5="CONFIRMED: NO MODS > 1YR","CONFIRMED: NO MODS > 1YR","DO NOT DELETE — not defensibly confirmed"),IF($Q5="HOLD","DO NOT DELETE — HOLD (Charlie review)",IF($Q5="KEEP","DO NOT DELETE — KEEP",IF(ISNUMBER(SEARCH("REVIEW",$Q5)),"DO NOT DELETE — REVIEW pending",$S5)))) -> CONFIRMED: NO MODS > 1YR | Q5: {=_xlfn.IFS(AND($A5="thg-beauty",ISNUMBER(SEARCH("liveramp",$C5))),"DELETE",$A5="agile-bonbon-662",_xlfn.IFS(LEFT($G5,9)="Tranche 1","DELETE",$C5="Sessions_Level_1_All_Sites","KEEP",ISNUMBER(--$C5),"REVIEW — UA raw logs",$C5="Emag_Reporting","KEEP",$C5="Nutrition_Data_Archived_Tables","KEEP",$C5="EU_Data","KEEP",TRUE,"REVIEW"),OR($A5="thg-influencer",$A5="thg-ingenuity",$A5="thg-central-marketing",$A5="thg-seoclarity"),"HOLD",TRUE,"")} | R5: {=_xlfn.IFS(AND($A5="thg-beauty",ISNUMBER(SEARCH("liveramp",$C5))),"thg-beauty Liveramp dataset — confirmed safe to delete",$A5="agile-bonbon-662",_xlfn.IFS(LEFT($G5,9)="Tranche 1","Tranche 1: cleared",$C5="Sessions_Level_1_All_Sites","Downstream aggregation of UA raw logs — keep if raw tables go",ISNUMBER(--$C5),"UA raw site logs (account ID) — keep pending audit-retention check",$C5="Emag_Reporting","Legacy but likely needed",$C5="Nutrition_Data_Archived_Tables","Worth keeping",$C5="EU_Data","Static lookup tables — scripts still reference (smoke-test risk)",TRUE,"Review"),OR($A5="thg-influencer",$A5="thg-ingenuity",$A5="thg-central-marketing",$A5="thg-seoclarity"),"HOLD — Charlie Stringer to review before deletion",TRUE,"")} | S5: CONFIRMED: NO MODS > 1YR
A6: thg-beauty | B6: eu | C6: Workspace_Sandbox | D6: No Description | E6: 2765.99 | F6: 55.32 | G6: Active | H6: Low | I6: 0 | J6: 0 | K6: 46197.451 | L6: 46197.39 | M6: 2026-06-24 10:49 (vy.nguyen12@thehutgroup.com) 2026-06-24 10:42 (vy.nguyen12@thehutgroup.com) 2026-06-24 10:41 (vy.nguyen12@thehutgroup.com) 2026-06-24 10:37 (vy.nguyen12@thehutgroup.com) 2026-06-24 10:36 (vy.nguyen12@thehutgroup.com) | N6: 2026-06-24 09:22 (aakash.kalantre61@thehutgroup.com) 2026-06-24 09:22 (aakash.kalantre61@thehutgroup.com) 2026-06-24 06:16 (amalu.thevalakara21@thg.com) 2026-06-24 06:10 (amalu.thevalakara21@thg.com) 2026-06-24 06:01 (aakash.kalantre61@thehutgroup.com) | O6: 46197.391 | P6: =IF($Q6="DELETE",IF($S6="CONFIRMED: NO MODS > 1YR","CONFIRMED: NO MODS > 1YR","DO NOT DELETE — not defensibly confirmed"),IF($Q6="HOLD","DO NOT DELETE — HOLD (Charlie review)",IF($Q6="KEEP","DO NOT DELETE — KEEP",IF(ISNUMBER(SEARCH("REVIEW",$Q6)),"DO NOT DELETE — REVIEW pending",$S6)))) -> CONFIRMED: NO MODS > 1YR | Q6: {=_xlfn.IFS(AND($A6="thg-beauty",ISNUMBER(SEARCH("liveramp",$C6))),"DELETE",$A6="agile-bonbon-662",_xlfn.IFS(LEFT($G6,9)="Tranche 1","DELETE",$C6="Sessions_Level_1_All_Sites","KEEP",ISNUMBER(--$C6),"REVIEW — UA raw logs",$C6="Emag_Reporting","KEEP",$C6="Nutrition_Data_Archived_Tables","KEEP",$C6="EU_Data","KEEP",TRUE,"REVIEW"),OR($A6="thg-influencer",$A6="thg-ingenuity",$A6="thg-central-marketing",$A6="thg-seoclarity"),"HOLD",TRUE,"")} | R6: {=_xlfn.IFS(AND($A6="thg-beauty",ISNUMBER(SEARCH("liveramp",$C6))),"thg-beauty Liveramp dataset — confirmed safe to delete",$A6="agile-bonbon-662",_xlfn.IFS(LEFT($G6,9)="Tranche 1","Tranche 1: cleared",$C6="Sessions_Level_1_All_Sites","Downstream aggregation of UA raw logs — keep if raw tables go",ISNUMBER(--$C6),"UA raw site logs (account ID) — keep pending audit-retention check",$C6="Emag_Reporting","Legacy but likely needed",$C6="Nutrition_Data_Archived_Tables","Worth keeping",$C6="EU_Data","Static lookup tables — scripts still reference (smoke-test risk)",TRUE,"Review"),OR($A6="thg-influencer",$A6="thg-ingenuity",$A6="thg-central-marketing",$A6="thg-seoclarity"),"HOLD — Charlie Stringer to review before deletion",TRUE,"")} | S6: CONFIRMED: NO MODS > 1YR
A7: thg-beauty | B7: eu | C7: Merch_WSSI | D7: No Description | E7: 2285.3 | F7: 45.71 | G7: Active | H7: Low | I7: 0 | J7: 0 | K7: 46197.337 | L7: 46197.296 | M7: 2026-06-24 08:04 (beauty-data@agile-bonbon-662.iam.gserviceaccount.com) 2026-06-24 07:31 (beauty-data@agile-bonbon-662.iam.gserviceaccount.com) 2026-06-24 07:31 (beauty-data@agile-bonbon-662.iam.gserviceaccount.com) 2026-06-24 07:27 (beauty-data@agile-bonbon-662.iam.gserviceaccount.com) 2026-06-24 07:27 (beauty-data@agile-bonbon-662.iam.gserviceaccount.com) | N7: 2026-06-24 07:06 (beauty-data@agile-bonbon-662.iam.gserviceaccount.com) 2026-06-24 06:52 (haleema.anbreen45@thg.com) 2026-06-24 06:47 (haleema.anbreen45@thg.com) 2026-06-24 05:11 (sa-bpswcbdsql01@thg-beauty.iam.gserviceaccount.com) 2026-06-24 05:00 (sa-bpswcbdsql01@thg-beauty.iam.gserviceaccount.com) | O7: 46197.296 | P7: =IF($Q7="DELETE",IF($S7="CONFIRMED: NO MODS > 1YR","CONFIRMED: NO MODS > 1YR","DO NOT DELETE — not defensibly confirmed"),IF($Q7="HOLD","DO NOT DELETE — HOLD (Charlie review)",IF($Q7="KEEP","DO NOT DELETE — KEEP",IF(ISNUMBER(SEARCH("REVIEW",$Q7)),"DO NOT DELETE — REVIEW pending",$S7)))) -> CONFIRMED: NO MODS > 1YR | Q7: {=_xlfn.IFS(AND($A7="thg-beauty",ISNUMBER(SEARCH("liveramp",$C7))),"DELETE",$A7="agile-bonbon-662",_xlfn.IFS(LEFT($G7,9)="Tranche 1","DELETE",$C7="Sessions_Level_1_All_Sites","KEEP",ISNUMBER(--$C7),"REVIEW — UA raw logs",$C7="Emag_Reporting","KEEP",$C7="Nutrition_Data_Archived_Tables","KEEP",$C7="EU_Data","KEEP",TRUE,"REVIEW"),OR($A7="thg-influencer",$A7="thg-ingenuity",$A7="thg-central-marketing",$A7="thg-seoclarity"),"HOLD",TRUE,"")} | R7: {=_xlfn.IFS(AND($A7="thg-beauty",ISNUMBER(SEARCH("liveramp",$C7))),"thg-beauty Liveramp dataset — confirmed safe to delete",$A7="agile-bonbon-662",_xlfn.IFS(LEFT($G7,9)="Tranche 1","Tranche 1: cleared",$C7="Sessions_Level_1_All_Sites","Downstream aggregation of UA raw logs — keep if raw tables go",ISNUMBER(--$C7),"UA raw site logs (account ID) — keep pending audit-retention check",$C7="Emag_Reporting","Legacy but likely needed",$C7="Nutrition_Data_Archived_Tables","Worth keeping",$C7="EU_Data","Static lookup tables — scripts still reference (smoke-test risk)",TRUE,"Review"),OR($A7="thg-influencer",$A7="thg-ingenuity",$A7="thg-central-marketing",$A7="thg-seoclarity"),"HOLD — Charlie Stringer to review before deletion",TRUE,"")} | S7: CONFIRMED: NO MODS > 1YR
A8: thg-beauty | B8: eu | C8: SUBS | D8: No Description | E8: 1922.79 | F8: 38.46 | G8: Active | H8: Low | I8: 0 | J8: 0 | K8: 46197.434 | L8: 46197.21 | M8: 2026-06-24 10:25 (sa-bpswcbdsql01@thg-beauty.iam.gserviceaccount.com) 2026-06-24 09:43 (aakash.kalantre61@thehutgroup.com) 2026-06-24 09:41 (aakash.kalantre61@thehutgroup.com) 2026-06-24 09:41 (aakash.kalantre61@thehutgroup.com) 2026-06-24 09:40 (aakash.kalantre61@thehutgroup.com) | N8: 2026-06-24 05:02 (sa-bpswcbdsql01@thg-beauty.iam.gserviceaccount.com) 2026-06-24 05:02 (sa-bpswcbdsql01@thg-beauty.iam.gserviceaccount.com) 2026-06-24 05:02 (sa-bpswcbdsql01@thg-beauty.iam.gserviceaccount.com) 2026-06-24 05:02 (sa-bpswcbdsql01@thg-beauty.iam.gserviceaccount.com) 2026-06-24 05:02 (sa-bpswcbdsql01@thg-beauty.iam.gserviceaccount.com) | O8: 46197.21 | P8: =IF($Q8="DELETE",IF($S8="CONFIRMED: NO MODS > 1YR","CONFIRMED: NO MODS > 1YR","DO NOT DELETE — not defensibly confirmed"),IF($Q8="HOLD","DO NOT DELETE — HOLD (Charlie review)",IF($Q8="KEEP","DO NOT DELETE — KEEP",IF(ISNUMBER(SEARCH("REVIEW",$Q8)),"DO NOT DELETE — REVIEW pending",$S8)))) -> CONFIRMED: NO MODS > 1YR | Q8: {=_xlfn.IFS(AND($A8="thg-beauty",ISNUMBER(SEARCH("liveramp",$C8))),"DELETE",$A8="agile-bonbon-662",_xlfn.IFS(LEFT($G8,9)="Tranche 1","DELETE",$C8="Sessions_Level_1_All_Sites","KEEP",ISNUMBER(--$C8),"REVIEW — UA raw logs",$C8="Emag_Reporting","KEEP",$C8="Nutrition_Data_Archived_Tables","KEEP",$C8="EU_Data","KEEP",TRUE,"REVIEW"),OR($A8="thg-influencer",$A8="thg-ingenuity",$A8="thg-central-marketing",$A8="thg-seoclarity"),"HOLD",TRUE,"")} | R8: {=_xlfn.IFS(AND($A8="thg-beauty",ISNUMBER(SEARCH("liveramp",$C8))),"thg-beauty Liveramp dataset — confirmed safe to delete",$A8="agile-bonbon-662",_xlfn.IFS(LEFT($G8,9)="Tranche 1","Tranche 1: cleared",$C8="Sessions_Level_1_All_Sites","Downstream aggregation of UA raw logs — keep if raw tables go",ISNUMBER(--$C8),"UA raw site logs (account ID) — keep pending audit-retention check",$C8="Emag_Reporting","Legacy but likely needed",$C8="Nutrition_Data_Archived_Tables","Worth keeping",$C8="EU_Data","Static lookup tables — scripts still reference (smoke-test risk)",TRUE,"Review"),OR($A8="thg-influencer",$A8="thg-ingenuity",$A8="thg-central-marketing",$A8="thg-seoclarity"),"HOLD — Charlie Stringer to review before deletion",TRUE,"")} | S8: CONFIRMED: NO MODS > 1YR
A9: thg-beauty | B9: eu | C9: Dataform_Sandbox | D9: No Description | E9: 1357.69 | F9: 27.15 | G9: Active | H9: Low | I9: 0 | J9: 0 | K9: 46197.175 | L9: 46197.109 | M9: 2026-06-24 04:12 (Liam.Lim79@thg.com) 2026-06-24 02:50 (sa-bpswcbdsql01@thg-beauty.iam.gserviceaccount.com) 2026-06-24 02:50 (sa-bpswcbdsql01@thg-beauty.iam.gserviceaccount.com) 2026-06-24 02:36 (sa-bpswcbdsql01@thg-beauty.iam.gserviceaccount.com) 2026-06-24 02:36 (sa-bpswcbdsql01@thg-beauty.iam.gserviceaccount.com) | N9: 2026-06-24 02:36 (sa-bpswcbdsql01@thg-beauty.iam.gserviceaccount.com) 2026-06-24 02:35 (sa-bpswcbdsql01@thg-beauty.iam.gserviceaccount.com) 2026-06-24 02:28 (sa-bpswcbdsql01@thg-beauty.iam.gserviceaccount.com) 2026-06-24 02:28 (sa-bpswcbdsql01@thg-beauty.iam.gserviceaccount.com) 2026-06-24 02:28 (sa-bpswcbdsql01@thg-beauty.iam.gserviceaccount.com) | O9: 46197.11 | P9: =IF($Q9="DELETE",IF($S9="CONFIRMED: NO MODS > 1YR","CONFIRMED: NO MODS > 1YR","DO NOT DELETE — not defensibly confirmed"),IF($Q9="HOLD","DO NOT DELETE — HOLD (Charlie review)",IF($Q9="KEEP","DO NOT DELETE — KEEP",IF(ISNUMBER(SEARCH("REVIEW",$Q9)),"DO NOT DELETE — REVIEW pending",$S9)))) -> CONFIRMED: NO MODS > 1YR | Q9: {=_xlfn.IFS(AND($A9="thg-beauty",ISNUMBER(SEARCH("liveramp",$C9))),"DELETE",$A9="agile-bonbon-662",_xlfn.IFS(LEFT($G9,9)="Tranche 1","DELETE",$C9="Sessions_Level_1_All_Sites","KEEP",ISNUMBER(--$C9),"REVIEW — UA raw logs",$C9="Emag_Reporting","KEEP",$C9="Nutrition_Data_Archived_Tables","KEEP",$C9="EU_Data","KEEP",TRUE,"REVIEW"),OR($A9="thg-influencer",$A9="thg-ingenuity",$A9="thg-central-marketing",$A9="thg-seoclarity"),"HOLD",TRUE,"")} | R9: {=_xlfn.IFS(AND($A9="thg-beauty",ISNUMBER(SEARCH("liveramp",$C9))),"thg-beauty Liveramp dataset — confirmed safe to delete",$A9="agile-bonbon-662",_xlfn.IFS(LEFT($G9,9)="Tranche 1","Tranche 1: cleared",$C9="Sessions_Level_1_All_Sites","Downstream aggregation of UA raw logs — keep if raw tables go",ISNUMBER(--$C9),"UA raw site logs (account ID) — keep pending audit-retention check",$C9="Emag_Reporting","Legacy but likely needed",$C9="Nutrition_Data_Archived_Tables","Worth keeping",$C9="EU_Data","Static lookup tables — scripts still reference (smoke-test risk)",TRUE,"Review"),OR($A9="thg-influencer",$A9="thg-ingenuity",$A9="thg-central-marketing",$A9="thg-seoclarity"),"HOLD — Charlie Stringer to review before deletion",TRUE,"")} | S9: CONFIRMED: NO MODS > 1YR
A10: thg-beauty | B10: eu | C10: Traffic_Data | D10: No Description | E10: 1302.1 | F10: 26.04 | G10: Active | H10: Low | I10: 0 | J10: 0 | K10: 46197.451 | L10: 46197.099 | M10: 2026-06-24 10:49 (vy.nguyen12@thehutgroup.com) 2026-06-24 10:42 (vy.nguyen12@thehutgroup.com) 2026-06-24 10:41 (vy.nguyen12@thehutgroup.com) 2026-06-24 10:37 (vy.nguyen12@thehutgroup.com) 2026-06-24 10:36 (vy.nguyen12@thehutgroup.com) | N10: 2026-06-24 02:23 (sa-bpswcbdsql01@thg-beauty.iam.gserviceaccount.com) 2026-06-24 02:23 (sa-bpswcbdsql01@thg-beauty.iam.gserviceaccount.com) 2026-06-24 02:23 (sa-bpswcbdsql01@thg-beauty.iam.gserviceaccount.com) 2026-06-24 02:23 (sa-bpswcbdsql01@thg-beauty.iam.gserviceaccount.com) 2026-06-24 02:23 (sa-bpswcbdsql01@thg-beauty.iam.gserviceaccount.com) | O10: 46197.1 | P10: =IF($Q10="DELETE",IF($S10="CONFIRMED: NO MODS > 1YR","CONFIRMED: NO MODS > 1YR","DO NOT DELETE — not defensibly confirmed"),IF($Q10="HOLD","DO NOT DELETE — HOLD (Charlie review)",IF($Q10="KEEP","DO NOT DELETE — KEEP",IF(ISNUMBER(SEARCH("REVIEW",$Q10)),"DO NOT DELETE — REVIEW pending",$S10)))) -> CONFIRMED: NO MODS > 1YR | Q10: {=_xlfn.IFS(AND($A10="thg-beauty",ISNUMBER(SEARCH("liveramp",$C10))),"DELETE",$A10="agile-bonbon-662",_xlfn.IFS(LEFT($G10,9)="Tranche 1","DELETE",$C10="Sessions_Level_1_All_Sites","KEEP",ISNUMBER(--$C10),"REVIEW — UA raw logs",$C10="Emag_Reporting","KEEP",$C10="Nutrition_Data_Archived_Tables","KEEP",$C10="EU_Data","KEEP",TRUE,"REVIEW"),OR($A10="thg-influencer",$A10="thg-ingenuity",$A10="thg-central-marketing",$A10="thg-seoclarity"),"HOLD",TRUE,"")} | R10: {=_xlfn.IFS(AND($A10="thg-beauty",ISNUMBER(SEARCH("liveramp",$C10))),"thg-beauty Liveramp dataset — confirmed safe to delete",$A10="agile-bonbon-662",_xlfn.IFS(LEFT($G10,9)="Tranche 1","Tranche 1: cleared",$C10="Sessions_Level_1_All_Sites","Downstream aggregation of UA raw logs — keep if raw tables go",ISNUMBER(--$C10),"UA raw site logs (account ID) — keep pending audit-retention check",$C10="Emag_Reporting","Legacy but likely needed",$C10="Nutrition_Data_Archived_Tables","Worth keeping",$C10="EU_Data","Static lookup tables — scripts still reference (smoke-test risk)",TRUE,"Review"),OR($A10="thg-influencer",$A10="thg-ingenuity",$A10="thg-central-marketing",$A10="thg-seoclarity"),"HOLD — Charlie Stringer to review before deletion",TRUE,"")} | S10: CONFIRMED: NO MODS > 1YR
A11: thg-beauty | B11: eu | C11: Retention | D11: No Description | E11: 850.97 | F11: 17.02 | G11: Active | H11: Low | I11: 0 | J11: 0 | K11: 46197.423 | L11: 46197.313 | M11: 2026-06-24 10:09 (beauty-data@agile-bonbon-662.iam.gserviceaccount.com) 2026-06-24 10:05 (beauty-data@agile-bonbon-662.iam.gserviceaccount.com) 2026-06-24 10:05 (beauty-data@agile-bonbon-662.iam.gserviceaccount.com) 2026-06-24 10:05 (beauty-data@agile-bonbon-662.iam.gserviceaccount.com) 2026-06-24 10:05 (beauty-data@agile-bonbon-662.iam.gserviceaccount.com) | N11: 2026-06-24 07:30 (Liam.Lim79@thg.com) 2026-06-24 06:15 (amalu.thevalakara21@thg.com) 2026-06-24 06:15 (amalu.thevalakara21@thg.com) 2026-06-24 06:10 (amalu.thevalakara21@thg.com) 2026-06-24 05:12 (sa-bpswcbdsql01@thg-beauty.iam.gserviceaccount.com) | O11: 46197.313 | P11: =IF($Q11="DELETE",IF($S11="CONFIRMED: NO MODS > 1YR","CONFIRMED: NO MODS > 1YR","DO NOT DELETE — not defensibly confirmed"),IF($Q11="HOLD","DO NOT DELETE — HOLD (Charlie review)",IF($Q11="KEEP","DO NOT DELETE — KEEP",IF(ISNUMBER(SEARCH("REVIEW",$Q11)),"DO NOT DELETE — REVIEW pending",$S11)))) -> CONFIRMED: NO MODS > 1YR | Q11: {=_xlfn.IFS(AND($A11="thg-beauty",ISNUMBER(SEARCH("liveramp",$C11))),"DELETE",$A11="agile-bonbon-662",_xlfn.IFS(LEFT($G11,9)="Tranche 1","DELETE",$C11="Sessions_Level_1_All_Sites","KEEP",ISNUMBER(--$C11),"REVIEW — UA raw logs",$C11="Emag_Reporting","KEEP",$C11="Nutrition_Data_Archived_Tables","KEEP",$C11="EU_Data","KEEP",TRUE,"REVIEW"),OR($A11="thg-influencer",$A11="thg-ingenuity",$A11="thg-central-marketing",$A11="thg-seoclarity"),"HOLD",TRUE,"")} | R11: {=_xlfn.IFS(AND($A11="thg-beauty",ISNUMBER(SEARCH("liveramp",$C11))),"thg-beauty Liveramp dataset — confirmed safe to delete",$A11="agile-bonbon-662",_xlfn.IFS(LEFT($G11,9)="Tranche 1","Tranche 1: cleared",$C11="Sessions_Level_1_All_Sites","Downstream aggregation of UA raw logs — keep if raw tables go",ISNUMBER(--$C11),"UA raw site logs (account ID) — keep pending audit-retention check",$C11="Emag_Reporting","Legacy but likely needed",$C11="Nutrition_Data_Archived_Tables","Worth keeping",$C11="EU_Data","Static lookup tables — scripts still reference (smoke-test risk)",TRUE,"Review"),OR($A11="thg-influencer",$A11="thg-ingenuity",$A11="thg-central-marketing",$A11="thg-seoclarity"),"HOLD — Charlie Stringer to review before deletion",TRUE,"")} | S11: CONFIRMED: NO MODS > 1YR
A12: thg-beauty | B12: eu | C12: Foundation_Finder | D12: No Description | E12: 740.27 | F12: 14.81 | G12: Active | H12: Low | I12: 0 | J12: 0 | K12: 46197.336 | L12: 46197.107 | M12: 2026-06-24 08:03 (beauty-data@agile-bonbon-662.iam.gserviceaccount.com) 2026-06-24 08:03 (beauty-data@agile-bonbon-662.iam.gserviceaccount.com) 2026-06-24 08:03 (beauty-data@agile-bonbon-662.iam.gserviceaccount.com) 2026-06-24 08:03 (beauty-data@agile-bonbon-662.iam.gserviceaccount.com) 2026-06-24 08:02 (beauty-data@agile-bonbon-662.iam.gserviceaccount.com) | N12: 2026-06-24 02:34 (sa-bpswcbdsql01@thg-beauty.iam.gserviceaccount.com) 2026-06-24 02:34 (sa-bpswcbdsql01@thg-beauty.iam.gserviceaccount.com) 2026-06-24 02:34 (sa-bpswcbdsql01@thg-beauty.iam.gserviceaccount.com) 2026-06-24 02:34 (sa-bpswcbdsql01@thg-beauty.iam.gserviceaccount.com) 2026-06-24 02:34 (sa-bpswcbdsql01@thg-beauty.iam.gserviceaccount.com) | O12: 46197.107 | P12: =IF($Q12="DELETE",IF($S12="CONFIRMED: NO MODS > 1YR","CONFIRMED: NO MODS > 1YR","DO NOT DELETE — not defensibly confirmed"),IF($Q12="HOLD","DO NOT DELETE — HOLD (Charlie review)",IF($Q12="KEEP","DO NOT DELETE — KEEP",IF(ISNUMBER(SEARCH("REVIEW",$Q12)),"DO NOT DELETE — REVIEW pending",$S12)))) -> CONFIRMED: NO MODS > 1YR | Q12: {=_xlfn.IFS(AND($A12="thg-beauty",ISNUMBER(SEARCH("liveramp",$C12))),"DELETE",$A12="agile-bonbon-662",_xlfn.IFS(LEFT($G12,9)="Tranche 1","DELETE",$C12="Sessions_Level_1_All_Sites","KEEP",ISNUMBER(--$C12),"REVIEW — UA raw logs",$C12="Emag_Reporting","KEEP",$C12="Nutrition_Data_Archived_Tables","KEEP",$C12="EU_Data","KEEP",TRUE,"REVIEW"),OR($A12="thg-influencer",$A12="thg-ingenuity",$A12="thg-central-marketing",$A12="thg-seoclarity"),"HOLD",TRUE,"")} | R12: {=_xlfn.IFS(AND($A12="thg-beauty",ISNUMBER(SEARCH("liveramp",$C12))),"thg-beauty Liveramp dataset — confirmed safe to delete",$A12="agile-bonbon-662",_xlfn.IFS(LEFT($G12,9)="Tranche 1","Tranche 1: cleared",$C12="Sessions_Level_1_All_Sites","Downstream aggregation of UA raw logs — keep if raw tables go",ISNUMBER(--$C12),"UA raw site logs (account ID) — keep pending audit-retention check",$C12="Emag_Reporting","Legacy but likely needed",$C12="Nutrition_Data_Archived_Tables","Worth keeping",$C12="EU_Data","Static lookup tables — scripts still reference (smoke-test risk)",TRUE,"Review"),OR($A12="thg-influencer",$A12="thg-ingenuity",$A12="thg-central-marketing",$A12="thg-seoclarity"),"HOLD — Charlie Stringer to review before deletion",TRUE,"")} | S12: CONFIRMED: NO MODS > 1YR
